Workbook

Sheet Raw Data
A1: Artist Name | B1: Sex | C1: Country of Origin | D1: Primary Language | E1: Primary Genre | F1: Artist Type | G1: Debut Year | H1: Total Streams (M) | I1: Lead Streams (M) | J1: Feature Streams (M) | K1: Solo Streams (M) | L1: % of Solo Streams | M1: Collaborative Streams (M) | N1: % of Collaborative Streams
A2: Drake | B2: Male | C2: Canada | D2: English | E2: Hip-Hop | F2: Solo | G2: 2006 | H2: 137492.1 | I2: 94851.1 | J2: 42640.9 | K2: 53323.9 | L2: 38.783246 | M2: 84168.2 | N2: 61.216754
A3: Taylor Swift | B3: Female | C3: United States | D3: English | E3: Pop | F3: Solo | G3: 2006 | H3: 127861 | I3: 126177.3 | J3: 1683.8 | K3: 113421.5 | L3: 88.706877 | M3: 14439.5 | N3: 11.293123
A4: Bad Bunny | B4: Male | C4: United States | D4: Spanish | E4: Reggaeton | F4: Solo | G4: 2013 | H4: 125899.8 | I4: 82189.3 | J4: 43710.5 | K4: 48887 | L4: 38.830086 | M4: 77012.8 | N4: 61.169914
A5: The Weeknd | B5: Male | C5: Canada | D5: English | E5: R&B | F5: Solo | G5: 2009 | H5: 95703.2 | I5: 77189.4 | J5: 18513.8 | K5: 51020 | L5: 53.310652 | M5: 44683.2 | N5: 46.689348
A6: Justin Bieber | B6: Male | C6: Canada | D6: English | E6: Pop | F6: Solo | G6: 2009 | H6: 78104.4 | I6: 48316.2 | J6: 29788.2 | K6: 29638.3 | L6: 37.94703 | M6: 48466.1 | N6: 62.05297
A7: Ariana Grande | B7: Female | C7: United States | D7: English | E7: Pop | F7: Solo | G7: 2013 | H7: 68298.9 | I7: 57097.5 | J7: 11201.4 | K7: 41615.5 | L7: 60.931435 | M7: 26683.4 | N7: 39.068565
A8: Travis Scott | B8: Male | C8: United States | D8: English | E8: Hip-Hop | F8: Solo | G8: 2013 | H8: 65349.7 | I8: 35338.7 | J8: 30027 | K8: 25309.9 | L8: 38.729941 | M8: 40039.8 | N8: 61.270059
A9: Kanye West | B9: Male | C9: United States | D9: English | E9: Hip-Hop | F9: Solo | G9: 2004 | H9: 65142.9 | I9: 46558.4 | J9: 18584.5 | K9: 28473 | L9: 43.708524 | M9: 36669.9 | N9: 56.291476
A10: Ed Sheeran | B10: Male | C10: United Kingdom | D10: English | E10: Pop | F10: Solo | G10: 2011 | H10: 64656.9 | I10: 57704 | J10: 6967.8 | K10: 46700 | L10: 72.227403 | M10: 17956.9 | N10: 27.772597
A11: Eminem | B11: Male | C11: United States | D11: English | E11: Hip-Hop | F11: Solo | G11: 1996 | H11: 64549 | I11: 54466.8 | J11: 10100.7 | K11: 32940 | L11: 51.031 | M11: 31609 | N11: 48.969
A12: Rihanna | B12: Female | C12: Barbados | D12: English | E12: Pop | F12: Solo | G12: 2005 | H12: 60670.7 | I12: 44824.4 | J12: 15846.4 | K12: 30261.8 | L12: 49.878772 | M12: 30408.9 | N12: 50.121228
A13: Billie Eilish | B13: Female | C13: United States | D13: English | E13: Pop | F13: Solo | G13: 2015 | H13: 58049.5 | I13: 57160.1 | J13: 889.4 | K13: 51567.9 | L13: 88.834357 | M13: 6481.6 | N13: 11.165643
... A501: Omar Courtz | B501: Male | C501: United States | D501: Spanish | E501: Reggaeton | F501: Solo | G501: 2017 | H501: 6972 | I501: 6956 | J501: 20.3 | K501: 1876.2 | L501: 26.910499 | M501: 5095.8 | N501: 73.089501

Sheet Cleaned Data
A1: Cleaned Data + Engineered Columns
A3: Cleaning check: 0 missing values, 0 duplicate rows/artist names found (verified programmatically) -- source data required no corrective cleaning. One header name was trimmed (" Artist Type" -> "Artist Type"). 3 columns were engineered below to answer the question set: Years Active, Streams per Year Active (momentum metric), and Era Bucket (career-stage segment).
A5: Reference year used for "Years Active" calculation: | C5: 2026
A7: Artist Name | B7: Sex | C7: Country of Origin | D7: Primary Language | E7: Primary Genre | F7: Artist Type | G7: Debut Year | H7: Total Streams (M) | I7: Lead Streams (M) | J7: Feature Streams (M) | K7: Solo Streams (M) | L7: % of Solo Streams | M7: Collaborative Streams (M) | N7: % of Collaborative Streams | O7: Years Active | P7: Streams per Year Active (M) | Q7: Era Bucket
A8: Drake | B8: Male | C8: Canada | D8: English | E8: Hip-Hop | F8: Solo | G8: 2006 | H8: 137492.1 | I8: 94851.1 | J8: 42640.9 | K8: 53323.9 | L8: 38.783246 | M8: 84168.2 | N8: 61.216754 | O8: =$C$5-G8 -> 20 | P8: =H8/O8 -> 6874.605 | Q8: =IF(G8<2010,"Legacy (pre-2010)",IF(G8<=2017,"Established (2010-2017)","Emerging (2018+)")) -> Legacy (pre-2010)
A9: Taylor Swift | B9: Female | C9: United States | D9: English | E9: Pop | F9: Solo | G9: 2006 | H9: 127861 | I9: 126177.3 | J9: 1683.8 | K9: 113421.5 | L9: 88.706877 | M9: 14439.5 | N9: 11.293123 | O9: =$C$5-G9 -> 20 | P9: =H9/O9 -> 6393.05 | Q9: =IF(G9<2010,"Legacy (pre-2010)",IF(G9<=2017,"Established (2010-2017)","Emerging (2018+)")) -> Legacy (pre-2010)
A10: Bad Bunny | B10: Male | C10: United States | D10: Spanish | E10: Reggaeton | F10: Solo | G10: 2013 | H10: 125899.8 | I10: 82189.3 | J10: 43710.5 | K10: 48887 | L10: 38.830086 | M10: 77012.8 | N10: 61.169914 | O10: =$C$5-G10 -> 13 | P10: =H10/O10 -> 9684.6 | Q10: =IF(G10<2010,"Legacy (pre-2010)",IF(G10<=2017,"Established (2010-2017)","Emerging (2018+)")) -> Established (2010-2017)
A11: The Weeknd | B11: Male | C11: Canada | D11: English | E11: R&B | F11: Solo | G11: 2009 | H11: 95703.2 | I11: 77189.4 | J11: 18513.8 | K11: 51020 | L11: 53.310652 | M11: 44683.2 | N11: 46.689348 | O11: =$C$5-G11 -> 17 | P11: =H11/O11 -> 5629.6 | Q11: =IF(G11<2010,"Legacy (pre-2010)",IF(G11<=2017,"Established (2010-2017)","Emerging (2018+)")) -> Legacy (pre-2010)
A12: Justin Bieber | B12: Male | C12: Canada | D12: English | E12: Pop | F12: Solo | G12: 2009 | H12: 78104.4 | I12: 48316.2 | J12: 29788.2 | K12: 29638.3 | L12: 37.94703 | M12: 48466.1 | N12: 62.05297 | O12: =$C$5-G12 -> 17 | P12: =H12/O12 -> 4594.3765 | Q12: =IF(G12<2010,"Legacy (pre-2010)",IF(G12<=2017,"Established (2010-2017)","Emerging (2018+)")) -> Legacy (pre-2010)
A13: Ariana Grande | B13: Female | C13: United States | D13: English | E13: Pop | F13: Solo | G13: 2013 | H13: 68298.9 | I13: 57097.5 | J13: 11201.4 | K13: 41615.5 | L13: 60.931435 | M13: 26683.4 | N13: 39.068565 | O13: =$C$5-G13 -> 13 | P13: =H13/O13 -> 5253.7615 | Q13: =IF(G13<2010,"Legacy (pre-2010)",IF(G13<=2017,"Established (2010-2017)","Emerging (2018+)")) -> Established (2010-2017)
A14: Travis Scott | B14: Male | C14: United States | D14: English | E14: Hip-Hop | F14: Solo | G14: 2013 | H14: 65349.7 | I14: 35338.7 | J14: 30027 | K14: 25309.9 | L14: 38.729941 | M14: 40039.8 | N14: 61.270059 | O14: =$C$5-G14 -> 13 | P14: =H14/O14 -> 5026.9 | Q14: =IF(G14<2010,"Legacy (pre-2010)",IF(G14<=2017,"Established (2010-2017)","Emerging (2018+)")) -> Established (2010-2017)
A15: Kanye West | B15: Male | C15: United States | D15: English | E15: Hip-Hop | F15: Solo | G15: 2004 | H15: 65142.9 | I15: 46558.4 | J15: 18584.5 | K15: 28473 | L15: 43.708524 | M15: 36669.9 | N15: 56.291476 | O15: =$C$5-G15 -> 22 | P15: =H15/O15 -> 2961.0409 | Q15: =IF(G15<2010,"Legacy (pre-2010)",IF(G15<=2017,"Established (2010-2017)","Emerging (2018+)")) -> Legacy (pre-2010)
A16: Ed Sheeran | B16: Male | C16: United Kingdom | D16: English | E16: Pop | F16: Solo | G16: 2011 | H16: 64656.9 | I16: 57704 | J16: 6967.8 | K16: 46700 | L16: 72.227403 | M16: 17956.9 | N16: 27.772597 | O16: =$C$5-G16 -> 15 | P16: =H16/O16 -> 4310.46 | Q16: =IF(G16<2010,"Legacy (pre-2010)",IF(G16<=2017,"Established (2010-2017)","Emerging (2018+)")) -> Established (2010-2017)
A17: Eminem | B17: Male | C17: United States | D17: English | E17: Hip-Hop | F17: Solo | G17: 1996 | H17: 64549 | I17: 54466.8 | J17: 10100.7 | K17: 32940 | L17: 51.031 | M17: 31609 | N17: 48.969 | O17: =$C$5-G17 -> 30 | P17: =H17/O17 -> 2151.6333 | Q17: =IF(G17<2010,"Legacy (pre-2010)",IF(G17<=2017,"Established (2010-2017)","Emerging (2018+)")) -> Legacy (pre-2010)
A18: Rihanna | B18: Female | C18: Barbados | D18: English | E18: Pop | F18: Solo | G18: 2005 | H18: 60670.7 | I18: 44824.4 | J18: 15846.4 | K18: 30261.8 | L18: 49.878772 | M18: 30408.9 | N18: 50.121228 | O18: =$C$5-G18 -> 21 | P18: =H18/O18 -> 2889.081 | Q18: =IF(G18<2010,"Legacy (pre-2010)",IF(G18<=2017,"Established (2010-2017)","Emerging (2018+)")) -> Legacy (pre-2010)
A19: Billie Eilish | B19: Female | C19: United States | D19: English | E19: Pop | F19: Solo | G19: 2015 | H19: 58049.5 | I19: 57160.1 | J19: 889.4 | K19: 51567.9 | L19: 88.834357 | M19: 6481.6 | N19: 11.165643 | O19: =$C$5-G19 -> 11 | P19: =H19/O19 -> 5277.2273 | Q19: =IF(G19<2010,"Legacy (pre-2010)",IF(G19<=2017,"Established (2010-2017)","Emerging (2018+)")) -> Established (2010-2017)
... A507: Omar Courtz | B507: Male | C507: United States | D507: Spanish | E507: Reggaeton | F507: Solo | G507: 2017 | H507: 6972 | I507: 6956 | J507: 20.3 | K507: 1876.2 | L507: 26.910499 | M507: 5095.8 | N507: 73.089501 | O507: =$C$5-G507 -> 9 | P507: =H507/O507 -> 774.66667 | Q507: =IF(G507<2010,"Legacy (pre-2010)",IF(G507<=2017,"Established (2010-2017)","Emerging (2018+)")) -> Established (2010-2017)

Sheet Questions
A1: Question Set for This Analysis
A3: No question set was provided for this run, so InsightFlow generated the following data-driven, decision-oriented questions -- basic to advanced -- based on the structure of this dataset (500 artists; genre, country, gender, artist-type, debut-year, and stream-split fields).
A5: # | B5: Question | C5: Answered in tab
A6: 1 | B6: [Overview] What do overall streaming numbers look like, and how do they break down by artist type and gender? | C6: Q1-2 Overview & Concentration
A7: 2 | B7: [Market concentration] Which countries and genres dominate total streams, and how concentrated is that dominance? | C7: Q1-2 Overview & Concentration
A8: 3 | B8: [Artist efficiency] Which artists generate the most streams per year since debut (momentum, not just raw totals)? | C8: Q3 Artist Efficiency
A9: 4 | B9: [Collaboration strategy] Does leaning into collaborations correlate with higher total streams, and does the pattern hold across genres? | C9: Q4 Collab Strategy
A10: 5 | B10: [Whitespace segments] Which genre segments post above-average streams per artist but have few artists in them -- i.e. where is the underserved opportunity? | C10: Q5 Whitespace Segments
A11: 6 | B11: [Legacy vs. emerging] How does performance differ between artists who debuted pre-2010, 2010-2017, and 2018+, and what does that imply for catalog vs. new-talent investment? | C11: Q6 Legacy vs Emerging
A12: 7 | B12: [Gender patterns] Are there meaningful streaming or collaboration differences by gender relevant to A&R/marketing decisions? | C12: Q7 Gender Patterns
A13: 8 | B13: [Capstone] Based on all of the above, what are the top actionable levers for maximizing streaming performance? | C13: Conclusions

Sheet Q1-2 Overview & Concentration
A1: Q1: Overview | Q2: Market Concentration
A3: Overall Dataset Summary
A4: Total Artists | B4: =COUNTA('Cleaned Data'!$A$8:$A$507) -> 500
A5: Sum of Total Streams (M) | B5: =SUM('Cleaned Data'!$H$8:$H$507) -> 8408805.1
A6: Average Total Streams per Artist (M) | B6: =AVERAGE('Cleaned Data'!$H$8:$H$507) -> 16817.61
A7: Median Total Streams (M) | B7: =MEDIAN('Cleaned Data'!$H$8:$H$507) -> 11923.25
A9: By Artist Type
A10: Artist Type | B10: Count | C10: Sum Streams (M) | D10: Avg Streams (M)
A11: Solo | B11: =COUNTIF('Cleaned Data'!$F$8:$F$507,A11) -> 373 | C11: =SUMIF('Cleaned Data'!$F$8:$F$507,A11,'Cleaned Data'!$H$8:$H$507) -> 6720958.2 | D11: =AVERAGEIF('Cleaned Data'!$F$8:$F$507,A11,'Cleaned Data'!$H$8:$H$507) -> 18018.655
A12: Group | B12: =COUNTIF('Cleaned Data'!$F$8:$F$507,A12) -> 127 | C12: =SUMIF('Cleaned Data'!$F$8:$F$507,A12,'Cleaned Data'!$H$8:$H$507) -> 1687846.9 | D12: =AVERAGEIF('Cleaned Data'!$F$8:$F$507,A12,'Cleaned Data'!$H$8:$H$507) -> 13290.133
A14: By Gender
A15: Sex | B15: Count | C15: Sum Streams (M) | D15: Avg Streams (M)
A16: Male | B16: =COUNTIF('Cleaned Data'!$B$8:$B$507,A16) -> 390 | C16: =SUMIF('Cleaned Data'!$B$8:$B$507,A16,'Cleaned Data'!$H$8:$H$507) -> 6438037.3 | D16: =AVERAGEIF('Cleaned Data'!$B$8:$B$507,A16,'Cleaned Data'!$H$8:$H$507) -> 16507.788
A17: Female | B17: =COUNTIF('Cleaned Data'!$B$8:$B$507,A17) -> 88 | C17: =SUMIF('Cleaned Data'!$B$8:$B$507,A17,'Cleaned Data'!$H$8:$H$507) -> 1636227.7 | D17: =AVERAGEIF('Cleaned Data'!$B$8:$B$507,A17,'Cleaned Data'!$H$8:$H$507) -> 18593.497
A18: Mixed | B18: =COUNTIF('Cleaned Data'!$B$8:$B$507,A18) -> 22 | C18: =SUMIF('Cleaned Data'!$B$8:$B$507,A18,'Cleaned Data'!$H$8:$H$507) -> 334540.1 | D18: =AVERAGEIF('Cleaned Data'!$B$8:$B$507,A18,'Cleaned Data'!$H$8:$H$507) -> 15206.368
A20: Genre Concentration (all 23 genres, ranked by share of total streams, cumulative %)
A21: Genre | B21: Count | C21: Sum Streams (M) | D21: % of Total | E21: Cumulative %
A22: Hip-Hop | B22: =COUNTIF('Cleaned Data'!$E$8:$E$507,A22) -> 115 | C22: =SUMIF('Cleaned Data'!$E$8:$E$507,A22,'Cleaned Data'!$H$8:$H$507) -> 2126055.1 | D22: =C22/SUM('Cleaned Data'!$H$8:$H$507) -> 0.25283677 | E22: =D22 -> 0.25283677
A23: Pop | B23: =COUNTIF('Cleaned Data'!$E$8:$E$507,A23) -> 102 | C23: =SUMIF('Cleaned Data'!$E$8:$E$507,A23,'Cleaned Data'!$H$8:$H$507) -> 2003601.8 | D23: =C23/SUM('Cleaned Data'!$H$8:$H$507) -> 0.23827426 | E23: =E22+D23 -> 0.49111103
A24: Reggaeton | B24: =COUNTIF('Cleaned Data'!$E$8:$E$507,A24) -> 43 | C24: =SUMIF('Cleaned Data'!$E$8:$E$507,A24,'Cleaned Data'!$H$8:$H$507) -> 888855.1 | D24: =C24/SUM('Cleaned Data'!$H$8:$H$507) -> 0.10570528 | E24: =E23+D24 -> 0.59681631
A25: Rock | B25: =COUNTIF('Cleaned Data'!$E$8:$E$507,A25) -> 60 | C25: =SUMIF('Cleaned Data'!$E$8:$E$507,A25,'Cleaned Data'!$H$8:$H$507) -> 812082.6 | D25: =C25/SUM('Cleaned Data'!$H$8:$H$507) -> 0.096575267 | E25: =E24+D25 -> 0.69339157
A26: R&B | B26: =COUNTIF('Cleaned Data'!$E$8:$E$507,A26) -> 31 | C26: =SUMIF('Cleaned Data'!$E$8:$E$507,A26,'Cleaned Data'!$H$8:$H$507) -> 570698.4 | D26: =C26/SUM('Cleaned Data'!$H$8:$H$507) -> 0.067869144 | E26: =E25+D26 -> 0.76126072
A27: Latin | B27: =COUNTIF('Cleaned Data'!$E$8:$E$507,A27) -> 30 | C27: =SUMIF('Cleaned Data'!$E$8:$E$507,A27,'Cleaned Data'!$H$8:$H$507) -> 377962 | D27: =C27/SUM('Cleaned Data'!$H$8:$H$507) -> 0.04494836 | E27: =E26+D27 -> 0.80620908
A28: EDM | B28: =COUNTIF('Cleaned Data'!$E$8:$E$507,A28) -> 22 | C28: =SUMIF('Cleaned Data'!$E$8:$E$507,A28,'Cleaned Data'!$H$8:$H$507) -> 367096.9 | D28: =C28/SUM('Cleaned Data'!$H$8:$H$507) -> 0.04365625 | E28: =E27+D28 -> 0.84986533
A29: Regional Mexican | B29: =COUNTIF('Cleaned Data'!$E$8:$E$507,A29) -> 19 | C29: =SUMIF('Cleaned Data'!$E$8:$E$507,A29,'Cleaned Data'!$H$8:$H$507) -> 256013.5 | D29: =C29/SUM('Cleaned Data'!$H$8:$H$507) -> 0.030445883 | E29: =E28+D29 -> 0.88031121
A30: K-Pop | B30: =COUNTIF('Cleaned Data'!$E$8:$E$507,A30) -> 11 | C30: =SUMIF('Cleaned Data'!$E$8:$E$507,A30,'Cleaned Data'!$H$8:$H$507) -> 157338.7 | D30: =C30/SUM('Cleaned Data'!$H$8:$H$507) -> 0.018711184 | E30: =E29+D30 -> 0.89902239
A31: Filmi | B31: =COUNTIF('Cleaned Data'!$E$8:$E$507,A31) -> 11 | C31: =SUMIF('Cleaned Data'!$E$8:$E$507,A31,'Cleaned Data'!$H$8:$H$507) -> 151357.9 | D31: =C31/SUM('Cleaned Data'!$H$8:$H$507) -> 0.01799993 | E31: =E30+D31 -> 0.91702232
A32: Alternative | B32: =COUNTIF('Cleaned Data'!$E$8:$E$507,A32) -> 9 | C32: =SUMIF('Cleaned Data'!$E$8:$E$507,A32,'Cleaned Data'!$H$8:$H$507) -> 148227.3 | D32: =C32/SUM('Cleaned Data'!$H$8:$H$507) -> 0.017627629 | E32: =E31+D32 -> 0.93464995
A33: Country | B33: =COUNTIF('Cleaned Data'!$E$8:$E$507,A33) -> 10 | C33: =SUMIF('Cleaned Data'!$E$8:$E$507,A33,'Cleaned Data'!$H$8:$H$507) -> 130286.2 | D33: =C33/SUM('Cleaned Data'!$H$8:$H$507) -> 0.015494021 | E33: =E32+D33 -> 0.95014397
A34: Sertanjeo | B34: =COUNTIF('Cleaned Data'!$E$8:$E$507,A34) -> 9 | C34: =SUMIF('Cleaned Data'!$E$8:$E$507,A34,'Cleaned Data'!$H$8:$H$507) -> 104798.4 | D34: =C34/SUM('Cleaned Data'!$H$8:$H$507) -> 0.012462936 | E34: =E33+D34 -> 0.96260691
... A44: Nu Metal | B44: =COUNTIF('Cleaned Data'!$E$8:$E$507,A44) -> 1 | C44: =SUMIF('Cleaned Data'!$E$8:$E$507,A44,'Cleaned Data'!$H$8:$H$507) -> 7018.9 | D44: =C44/SUM('Cleaned Data'!$H$8:$H$507) -> 0.00083470837 | E44: =E43+D44 -> 1
A46: Top 10 Countries by Total Streams
A47: Country | B47: Count | C47: Sum Streams (M) | D47: % of Total
A48: United States | B48: =COUNTIF('Cleaned Data'!$C$8:$C$507,A48) -> 265 | C48: =SUMIF('Cleaned Data'!$C$8:$C$507,A48,'Cleaned Data'!$H$8:$H$507) -> 4786604 | D48: =C48/SUM('Cleaned Data'!$H$8:$H$507) -> 0.56923712
A49: United Kingdom | B49: =COUNTIF('Cleaned Data'!$C$8:$C$507,A49) -> 55 | C49: =SUMIF('Cleaned Data'!$C$8:$C$507,A49,'Cleaned Data'!$H$8:$H$507) -> 852177.8 | D49: =C49/SUM('Cleaned Data'!$H$8:$H$507) -> 0.10134351
A50: Canada | B50: =COUNTIF('Cleaned Data'!$C$8:$C$507,A50) -> 18 | C50: =SUMIF('Cleaned Data'!$C$8:$C$507,A50,'Cleaned Data'!$H$8:$H$507) -> 496760.3 | D50: =C50/SUM('Cleaned Data'!$H$8:$H$507) -> 0.059076206
A51: Mexico | B51: =COUNTIF('Cleaned Data'!$C$8:$C$507,A51) -> 27 | C51: =SUMIF('Cleaned Data'!$C$8:$C$507,A51,'Cleaned Data'!$H$8:$H$507) -> 332177.9 | D51: =C51/SUM('Cleaned Data'!$H$8:$H$507) -> 0.039503579
A52: Colombia | B52: =COUNTIF('Cleaned Data'!$C$8:$C$507,A52) -> 16 | C52: =SUMIF('Cleaned Data'!$C$8:$C$507,A52,'Cleaned Data'!$H$8:$H$507) -> 327813.8 | D52: =C52/SUM('Cleaned Data'!$H$8:$H$507) -> 0.038984588
A53: India | B53: =COUNTIF('Cleaned Data'!$C$8:$C$507,A53) -> 13 | C53: =SUMIF('Cleaned Data'!$C$8:$C$507,A53,'Cleaned Data'!$H$8:$H$507) -> 186954.7 | D53: =C53/SUM('Cleaned Data'!$H$8:$H$507) -> 0.022233206
A54: Brazil | B54: =COUNTIF('Cleaned Data'!$C$8:$C$507,A54) -> 15 | C54: =SUMIF('Cleaned Data'!$C$8:$C$507,A54,'Cleaned Data'!$H$8:$H$507) -> 164439 | D54: =C54/SUM('Cleaned Data'!$H$8:$H$507) -> 0.019555573
...

Sheet Q3 Artist Efficiency
A1: Q3: Artist Efficiency -- Streams per Year Since Debut
A3: Raw Total Streams rewards longevity as much as popularity. "Streams per Year Active" (Total Streams / Years since debut) surfaces artists building the fastest momentum, not just the biggest back catalog.
A6: Top 20 Artists by Streams per Year Active
A7: Rank | B7: Artist Name | C7: Debut Year | D7: Years Active | E7: Total Streams (M) | F7: Streams/Year Active (M)
A8: 1 | B8: Bad Bunny | C8: =INDEX('Cleaned Data'!$G$8:$G$507,MATCH(B8,'Cleaned Data'!$A$8:$A$507,0)) -> 2013 | D8: =INDEX('Cleaned Data'!$O$8:$O$507,MATCH(B8,'Cleaned Data'!$A$8:$A$507,0)) -> 13 | E8: =INDEX('Cleaned Data'!$H$8:$H$507,MATCH(B8,'Cleaned Data'!$A$8:$A$507,0)) -> 125899.8 | F8: =INDEX('Cleaned Data'!$P$8:$P$507,MATCH(B8,'Cleaned Data'!$A$8:$A$507,0)) -> 9684.6
A9: 2 | B9: Drake | C9: =INDEX('Cleaned Data'!$G$8:$G$507,MATCH(B9,'Cleaned Data'!$A$8:$A$507,0)) -> 2006 | D9: =INDEX('Cleaned Data'!$O$8:$O$507,MATCH(B9,'Cleaned Data'!$A$8:$A$507,0)) -> 20 | E9: =INDEX('Cleaned Data'!$H$8:$H$507,MATCH(B9,'Cleaned Data'!$A$8:$A$507,0)) -> 137492.1 | F9: =INDEX('Cleaned Data'!$P$8:$P$507,MATCH(B9,'Cleaned Data'!$A$8:$A$507,0)) -> 6874.605
A10: 3 | B10: Taylor Swift | C10: =INDEX('Cleaned Data'!$G$8:$G$507,MATCH(B10,'Cleaned Data'!$A$8:$A$507,0)) -> 2006 | D10: =INDEX('Cleaned Data'!$O$8:$O$507,MATCH(B10,'Cleaned Data'!$A$8:$A$507,0)) -> 20 | E10: =INDEX('Cleaned Data'!$H$8:$H$507,MATCH(B10,'Cleaned Data'!$A$8:$A$507,0)) -> 127861 | F10: =INDEX('Cleaned Data'!$P$8:$P$507,MATCH(B10,'Cleaned Data'!$A$8:$A$507,0)) -> 6393.05
A11: 4 | B11: Olivia Rodrigo | C11: =INDEX('Cleaned Data'!$G$8:$G$507,MATCH(B11,'Cleaned Data'!$A$8:$A$507,0)) -> 2021 | D11: =INDEX('Cleaned Data'!$O$8:$O$507,MATCH(B11,'Cleaned Data'!$A$8:$A$507,0)) -> 5 | E11: =INDEX('Cleaned Data'!$H$8:$H$507,MATCH(B11,'Cleaned Data'!$A$8:$A$507,0)) -> 28799.7 | F11: =INDEX('Cleaned Data'!$P$8:$P$507,MATCH(B11,'Cleaned Data'!$A$8:$A$507,0)) -> 5759.94
A12: 5 | B12: The Weeknd | C12: =INDEX('Cleaned Data'!$G$8:$G$507,MATCH(B12,'Cleaned Data'!$A$8:$A$507,0)) -> 2009 | D12: =INDEX('Cleaned Data'!$O$8:$O$507,MATCH(B12,'Cleaned Data'!$A$8:$A$507,0)) -> 17 | E12: =INDEX('Cleaned Data'!$H$8:$H$507,MATCH(B12,'Cleaned Data'!$A$8:$A$507,0)) -> 95703.2 | F12: =INDEX('Cleaned Data'!$P$8:$P$507,MATCH(B12,'Cleaned Data'!$A$8:$A$507,0)) -> 5629.6
A13: 6 | B13: Peso Pluma | C13: =INDEX('Cleaned Data'!$G$8:$G$507,MATCH(B13,'Cleaned Data'!$A$8:$A$507,0)) -> 2020 | D13: =INDEX('Cleaned Data'!$O$8:$O$507,MATCH(B13,'Cleaned Data'!$A$8:$A$507,0)) -> 6 | E13: =INDEX('Cleaned Data'!$H$8:$H$507,MATCH(B13,'Cleaned Data'!$A$8:$A$507,0)) -> 33179.8 | F13: =INDEX('Cleaned Data'!$P$8:$P$507,MATCH(B13,'Cleaned Data'!$A$8:$A$507,0)) -> 5529.9667
A14: 7 | B14: Billie Eilish | C14: =INDEX('Cleaned Data'!$G$8:$G$507,MATCH(B14,'Cleaned Data'!$A$8:$A$507,0)) -> 2015 | D14: =INDEX('Cleaned Data'!$O$8:$O$507,MATCH(B14,'Cleaned Data'!$A$8:$A$507,0)) -> 11 | E14: =INDEX('Cleaned Data'!$H$8:$H$507,MATCH(B14,'Cleaned Data'!$A$8:$A$507,0)) -> 58049.5 | F14: =INDEX('Cleaned Data'!$P$8:$P$507,MATCH(B14,'Cleaned Data'!$A$8:$A$507,0)) -> 5277.2273
A15: 8 | B15: Ariana Grande | C15: =INDEX('Cleaned Data'!$G$8:$G$507,MATCH(B15,'Cleaned Data'!$A$8:$A$507,0)) -> 2013 | D15: =INDEX('Cleaned Data'!$O$8:$O$507,MATCH(B15,'Cleaned Data'!$A$8:$A$507,0)) -> 13 | E15: =INDEX('Cleaned Data'!$H$8:$H$507,MATCH(B15,'Cleaned Data'!$A$8:$A$507,0)) -> 68298.9 | F15: =INDEX('Cleaned Data'!$P$8:$P$507,MATCH(B15,'Cleaned Data'!$A$8:$A$507,0)) -> 5253.7615
A16: 9 | B16: Travis Scott | C16: =INDEX('Cleaned Data'!$G$8:$G$507,MATCH(B16,'Cleaned Data'!$A$8:$A$507,0)) -> 2013 | D16: =INDEX('Cleaned Data'!$O$8:$O$507,MATCH(B16,'Cleaned Data'!$A$8:$A$507,0)) -> 13 | E16: =INDEX('Cleaned Data'!$H$8:$H$507,MATCH(B16,'Cleaned Data'!$A$8:$A$507,0)) -> 65349.7 | F16: =INDEX('Cleaned Data'!$P$8:$P$507,MATCH(B16,'Cleaned Data'!$A$8:$A$507,0)) -> 5026.9
A17: 10 | B17: Tito Double P | C17: =INDEX('Cleaned Data'!$G$8:$G$507,MATCH(B17,'Cleaned Data'!$A$8:$A$507,0)) -> 2023 | D17: =INDEX('Cleaned Data'!$O$8:$O$507,MATCH(B17,'Cleaned Data'!$A$8:$A$507,0)) -> 3 | E17: =INDEX('Cleaned Data'!$H$8:$H$507,MATCH(B17,'Cleaned Data'!$A$8:$A$507,0)) -> 14166.6 | F17: =INDEX('Cleaned Data'!$P$8:$P$507,MATCH(B17,'Cleaned Data'!$A$8:$A$507,0)) -> 4722.2
A18: 11 | B18: Justin Bieber | C18: =INDEX('Cleaned Data'!$G$8:$G$507,MATCH(B18,'Cleaned Data'!$A$8:$A$507,0)) -> 2009 | D18: =INDEX('Cleaned Data'!$O$8:$O$507,MATCH(B18,'Cleaned Data'!$A$8:$A$507,0)) -> 17 | E18: =INDEX('Cleaned Data'!$H$8:$H$507,MATCH(B18,'Cleaned Data'!$A$8:$A$507,0)) -> 78104.4 | F18: =INDEX('Cleaned Data'!$P$8:$P$507,MATCH(B18,'Cleaned Data'!$A$8:$A$507,0)) -> 4594.3765
A19: 12 | B19: Ed Sheeran | C19: =INDEX('Cleaned Data'!$G$8:$G$507,MATCH(B19,'Cleaned Data'!$A$8:$A$507,0)) -> 2011 | D19: =INDEX('Cleaned Data'!$O$8:$O$507,MATCH(B19,'Cleaned Data'!$A$8:$A$507,0)) -> 15 | E19: =INDEX('Cleaned Data'!$H$8:$H$507,MATCH(B19,'Cleaned Data'!$A$8:$A$507,0)) -> 64656.9 | F19: =INDEX('Cleaned Data'!$P$8:$P$507,MATCH(B19,'Cleaned Data'!$A$8:$A$507,0)) -> 4310.46
... A27: 20 | B27: Bruno Mars | C27: =INDEX('Cleaned Data'!$G$8:$G$507,MATCH(B27,'Cleaned Data'!$A$8:$A$507,0)) -> 2010 | D27: =INDEX('Cleaned Data'!$O$8:$O$507,MATCH(B27,'Cleaned Data'!$A$8:$A$507,0)) -> 16 | E27: =INDEX('Cleaned Data'!$H$8:$H$507,MATCH(B27,'Cleaned Data'!$A$8:$A$507,0)) -> 56727.1 | F27: =INDEX('Cleaned Data'!$P$8:$P$507,MATCH(B27,'Cleaned Data'!$A$8:$A$507,0)) -> 3545.4437

Sheet Q4 Collab Strategy
A1: Q4: Does Collaboration Strategy Drive Higher Streams?
A3: Overall correlation: % Collaborative Streams vs. Total Streams
A4: Correlation coefficient (CORREL) | B4: =CORREL('Cleaned Data'!$N$8:$N$507,'Cleaned Data'!$H$8:$H$507) -> 0.037487472
A5: Interpretation guide: near 0 = no linear relationship, near +/-1 = strong relationship
A7: Total Streams by Collaboration-Intensity Band
A8: Collaboration Band | B8: # Artists | C8: Avg Total Streams (M)
A9: 0-25% Collab | B9: =COUNTIFS('Cleaned Data'!$N$8:$N$507,">="&0,'Cleaned Data'!$N$8:$N$507,"<="&25) -> 163 | C9: =AVERAGEIFS('Cleaned Data'!$H$8:$H$507,'Cleaned Data'!$N$8:$N$507,">="&0,'Cleaned Data'!$N$8:$N$507,"<="&25) -> 14261.454
A10: 25-50% Collab | B10: =COUNTIFS('Cleaned Data'!$N$8:$N$507,">"&25,'Cleaned Data'!$N$8:$N$507,"<="&50) -> 75 | C10: =AVERAGEIFS('Cleaned Data'!$H$8:$H$507,'Cleaned Data'!$N$8:$N$507,">"&25,'Cleaned Data'!$N$8:$N$507,"<="&50) -> 19946.409
A11: 50-75% Collab | B11: =COUNTIFS('Cleaned Data'!$N$8:$N$507,">"&50,'Cleaned Data'!$N$8:$N$507,"<="&75) -> 116 | C11: =AVERAGEIFS('Cleaned Data'!$H$8:$H$507,'Cleaned Data'!$N$8:$N$507,">"&50,'Cleaned Data'!$N$8:$N$507,"<="&75) -> 20433.359
A12: 75-100% Collab | B12: =COUNTIFS('Cleaned Data'!$N$8:$N$507,">"&75,'Cleaned Data'!$N$8:$N$507,"<="&100.01) -> 146 | C12: =AVERAGEIFS('Cleaned Data'!$H$8:$H$507,'Cleaned Data'!$N$8:$N$507,">"&75,'Cleaned Data'!$N$8:$N$507,"<="&100.01) -> 15191.355
A14: Does the pattern hold across the 5 biggest genres?
A15: Genre | B15: # Artists | C15: Avg % Collaborative | D15: Avg Total Streams (M)
A16: Hip-Hop | B16: =COUNTIF('Cleaned Data'!$E$8:$E$507,A16) -> 115 | C16: =AVERAGEIF('Cleaned Data'!$E$8:$E$507,A16,'Cleaned Data'!$N$8:$N$507) -> 66.922826 | D16: =AVERAGEIF('Cleaned Data'!$E$8:$E$507,A16,'Cleaned Data'!$H$8:$H$507) -> 18487.436
A17: Pop | B17: =COUNTIF('Cleaned Data'!$E$8:$E$507,A17) -> 102 | C17: =AVERAGEIF('Cleaned Data'!$E$8:$E$507,A17,'Cleaned Data'!$N$8:$N$507) -> 38.784539 | D17: =AVERAGEIF('Cleaned Data'!$E$8:$E$507,A17,'Cleaned Data'!$H$8:$H$507) -> 19643.155
A18: Reggaeton | B18: =COUNTIF('Cleaned Data'!$E$8:$E$507,A18) -> 43 | C18: =AVERAGEIF('Cleaned Data'!$E$8:$E$507,A18,'Cleaned Data'!$N$8:$N$507) -> 83.616688 | D18: =AVERAGEIF('Cleaned Data'!$E$8:$E$507,A18,'Cleaned Data'!$H$8:$H$507) -> 20671.049
A19: Rock | B19: =COUNTIF('Cleaned Data'!$E$8:$E$507,A19) -> 60 | C19: =AVERAGEIF('Cleaned Data'!$E$8:$E$507,A19,'Cleaned Data'!$N$8:$N$507) -> 6.1702964 | D19: =AVERAGEIF('Cleaned Data'!$E$8:$E$507,A19,'Cleaned Data'!$H$8:$H$507) -> 13534.71
A20: R&B | B20: =COUNTIF('Cleaned Data'!$E$8:$E$507,A20) -> 31 | C20: =AVERAGEIF('Cleaned Data'!$E$8:$E$507,A20,'Cleaned Data'!$N$8:$N$507) -> 53.833003 | D20: =AVERAGEIF('Cleaned Data'!$E$8:$E$507,A20,'Cleaned Data'!$H$8:$H$507) -> 18409.626

Sheet Q5 Whitespace Segments
A1: Q5: Genre Whitespace -- High Avg. Streams, Low Artist Count
A3: Quadrant logic: a genre is a "Whitespace" opportunity if its average streams-per-artist is ABOVE the dataset average AND it has FEWER artists than the median genre -- i.e. proven demand, thin roster. Genres with fewer than 5 artists are flagged as low-confidence (single outlier artists can skew the average).
A6: Reference values
A7: Dataset average Total Streams (M) | B7: =AVERAGE('Cleaned Data'!$H$8:$H$507) -> 16817.61
A8: Median # artists per genre | B8: =MEDIAN(B12:B34) -> 9
A10: All 23 Genres -- Quadrant Classification (ranked by avg streams/artist)
A11: Genre | B11: # Artists | C11: Avg Streams/Artist (M) | D11: Reliable Sample (n>=5) | E11: Quadrant
A12: Spoken Word | B12: =COUNTIF('Cleaned Data'!$E$8:$E$507,A12) -> 1 | C12: =AVERAGEIF('Cleaned Data'!$E$8:$E$507,A12,'Cleaned Data'!$H$8:$H$507) -> 24607 | D12: =IF(B12>=5,"Yes","No (n<5)") -> No (n<5) | E12: =IF(AND(C12>$B$7,B12<$B$8),"Whitespace opportunity",IF(AND(C12>$B$7,B12>=$B$8),"Saturated (strong but crowded)",IF(AND(C12<=$B$7,B12<$B$8),"Niche (small & below avg)","Low priority (crowded & below avg)"))) -> Whitespace opportunity
A13: Reggaeton | B13: =COUNTIF('Cleaned Data'!$E$8:$E$507,A13) -> 43 | C13: =AVERAGEIF('Cleaned Data'!$E$8:$E$507,A13,'Cleaned Data'!$H$8:$H$507) -> 20671.049 | D13: =IF(B13>=5,"Yes","No (n<5)") -> Yes | E13: =IF(AND(C13>$B$7,B13<$B$8),"Whitespace opportunity",IF(AND(C13>$B$7,B13>=$B$8),"Saturated (strong but crowded)",IF(AND(C13<=$B$7,B13<$B$8),"Niche (small & below avg)","Low priority (crowded & below avg)"))) -> Saturated (strong but crowded)
A14: Pop | B14: =COUNTIF('Cleaned Data'!$E$8:$E$507,A14) -> 102 | C14: =AVERAGEIF('Cleaned Data'!$E$8:$E$507,A14,'Cleaned Data'!$H$8:$H$507) -> 19643.155 | D14: =IF(B14>=5,"Yes","No (n<5)") -> Yes | E14: =IF(AND(C14>$B$7,B14<$B$8),"Whitespace opportunity",IF(AND(C14>$B$7,B14>=$B$8),"Saturated (strong but crowded)",IF(AND(C14<=$B$7,B14<$B$8),"Niche (small & below avg)","Low priority (crowded & below avg)"))) -> Saturated (strong but crowded)
A15: Hip-Hop | B15: =COUNTIF('Cleaned Data'!$E$8:$E$507,A15) -> 115 | C15: =AVERAGEIF('Cleaned Data'!$E$8:$E$507,A15,'Cleaned Data'!$H$8:$H$507) -> 18487.436 | D15: =IF(B15>=5,"Yes","No (n<5)") -> Yes | E15: =IF(AND(C15>$B$7,B15<$B$8),"Whitespace opportunity",IF(AND(C15>$B$7,B15>=$B$8),"Saturated (strong but crowded)",IF(AND(C15<=$B$7,B15<$B$8),"Niche (small & below avg)","Low priority (crowded & below avg)"))) -> Saturated (strong but crowded)
A16: R&B | B16: =COUNTIF('Cleaned Data'!$E$8:$E$507,A16) -> 31 | C16: =AVERAGEIF('Cleaned Data'!$E$8:$E$507,A16,'Cleaned Data'!$H$8:$H$507) -> 18409.626 | D16: =IF(B16>=5,"Yes","No (n<5)") -> Yes | E16: =IF(AND(C16>$B$7,B16<$B$8),"Whitespace opportunity",IF(AND(C16>$B$7,B16>=$B$8),"Saturated (strong but crowded)",IF(AND(C16<=$B$7,B16<$B$8),"Niche (small & below avg)","Low priority (crowded & below avg)"))) -> Saturated (strong but crowded)
A17: EDM | B17: =COUNTIF('Cleaned Data'!$E$8:$E$507,A17) -> 22 | C17: =AVERAGEIF('Cleaned Data'!$E$8:$E$507,A17,'Cleaned Data'!$H$8:$H$507) -> 16686.223 | D17: =IF(B17>=5,"Yes","No (n<5)") -> Yes | E17: =IF(AND(C17>$B$7,B17<$B$8),"Whitespace opportunity",IF(AND(C17>$B$7,B17>=$B$8),"Saturated (strong but crowded)",IF(AND(C17<=$B$7,B17<$B$8),"Niche (small & below avg)","Low priority (crowded & below avg)"))) -> Low priority (crowded & below avg)
A18: Reggae | B18: =COUNTIF('Cleaned Data'!$E$8:$E$507,A18) -> 2 | C18: =AVERAGEIF('Cleaned Data'!$E$8:$E$507,A18,'Cleaned Data'!$H$8:$H$507) -> 16598 | D18: =IF(B18>=5,"Yes","No (n<5)") -> No (n<5) | E18: =IF(AND(C18>$B$7,B18<$B$8),"Whitespace opportunity",IF(AND(C18>$B$7,B18>=$B$8),"Saturated (strong but crowded)",IF(AND(C18<=$B$7,B18<$B$8),"Niche (small & below avg)","Low priority (crowded & below avg)"))) -> Niche (small & below avg)
A19: Alternative | B19: =COUNTIF('Cleaned Data'!$E$8:$E$507,A19) -> 9 | C19: =AVERAGEIF('Cleaned Data'!$E$8:$E$507,A19,'Cleaned Data'!$H$8:$H$507) -> 16469.7 | D19: =IF(B19>=5,"Yes","No (n<5)") -> Yes | E19: =IF(AND(C19>$B$7,B19<$B$8),"Whitespace opportunity",IF(AND(C19>$B$7,B19>=$B$8),"Saturated (strong but crowded)",IF(AND(C19<=$B$7,B19<$B$8),"Niche (small & below avg)","Low priority (crowded & below avg)"))) -> Low priority (crowded & below avg)
A20: K-Pop | B20: =COUNTIF('Cleaned Data'!$E$8:$E$507,A20) -> 11 | C20: =AVERAGEIF('Cleaned Data'!$E$8:$E$507,A20,'Cleaned Data'!$H$8:$H$507) -> 14303.518 | D20: =IF(B20>=5,"Yes","No (n<5)") -> Yes | E20: =IF(AND(C20>$B$7,B20<$B$8),"Whitespace opportunity",IF(AND(C20>$B$7,B20>=$B$8),"Saturated (strong but crowded)",IF(AND(C20<=$B$7,B20<$B$8),"Niche (small & below avg)","Low priority (crowded & below avg)"))) -> Low priority (crowded & below avg)
A21: Filmi | B21: =COUNTIF('Cleaned Data'!$E$8:$E$507,A21) -> 11 | C21: =AVERAGEIF('Cleaned Data'!$E$8:$E$507,A21,'Cleaned Data'!$H$8:$H$507) -> 13759.809 | D21: =IF(B21>=5,"Yes","No (n<5)") -> Yes | E21: =IF(AND(C21>$B$7,B21<$B$8),"Whitespace opportunity",IF(AND(C21>$B$7,B21>=$B$8),"Saturated (strong but crowded)",IF(AND(C21<=$B$7,B21<$B$8),"Niche (small & below avg)","Low priority (crowded & below avg)"))) -> Low priority (crowded & below avg)
A22: Soundtrack | B22: =COUNTIF('Cleaned Data'!$E$8:$E$507,A22) -> 3 | C22: =AVERAGEIF('Cleaned Data'!$E$8:$E$507,A22,'Cleaned Data'!$H$8:$H$507) -> 13730.433 | D22: =IF(B22>=5,"Yes","No (n<5)") -> No (n<5) | E22: =IF(AND(C22>$B$7,B22<$B$8),"Whitespace opportunity",IF(AND(C22>$B$7,B22>=$B$8),"Saturated (strong but crowded)",IF(AND(C22<=$B$7,B22<$B$8),"Niche (small & below avg)","Low priority (crowded & below avg)"))) -> Niche (small & below avg)
A23: Bachata | B23: =COUNTIF('Cleaned Data'!$E$8:$E$507,A23) -> 3 | C23: =AVERAGEIF('Cleaned Data'!$E$8:$E$507,A23,'Cleaned Data'!$H$8:$H$507) -> 13550.467 | D23: =IF(B23>=5,"Yes","No (n<5)") -> No (n<5) | E23: =IF(AND(C23>$B$7,B23<$B$8),"Whitespace opportunity",IF(AND(C23>$B$7,B23>=$B$8),"Saturated (strong but crowded)",IF(AND(C23<=$B$7,B23<$B$8),"Niche (small & below avg)","Low priority (crowded & below avg)"))) -> Niche (small & below avg)
... A34: Nu Metal | B34: =COUNTIF('Cleaned Data'!$E$8:$E$507,A34) -> 1 | C34: =AVERAGEIF('Cleaned Data'!$E$8:$E$507,A34,'Cleaned Data'!$H$8:$H$507) -> 7018.9 | D34: =IF(B34>=5,"Yes","No (n<5)") -> No (n<5) | E34: =IF(AND(C34>$B$7,B34<$B$8),"Whitespace opportunity",IF(AND(C34>$B$7,B34>=$B$8),"Saturated (strong but crowded)",IF(AND(C34<=$B$7,B34<$B$8),"Niche (small & below avg)","Low priority (crowded & below avg)"))) -> Niche (small & below avg)
A36: Recommended Whitespace Opportunities (n>=5, reliable sample only)
A37: Genre | B37: # Artists | C37: Avg Streams/Artist (M)
A38: None met the n>=5 + above-average + below-median-count criteria in this dataset.

Sheet Q6 Legacy vs Emerging
A1: Q6: Legacy vs. Established vs. Emerging Artists
A3: Era Bucket (engineered on the Cleaned Data tab): Legacy = debuted before 2010, Established = 2010-2017, Emerging = 2018 or later.
A5: Era Bucket | B5: # Artists | C5: Avg Total Streams (M) | D5: Avg Streams/Year Active (M) | E5: Avg % Collaborative
A6: Legacy (pre-2010) | B6: =COUNTIF('Cleaned Data'!$Q$8:$Q$507,A6) -> 254 | C6: =AVERAGEIF('Cleaned Data'!$Q$8:$Q$507,A6,'Cleaned Data'!$H$8:$H$507) -> 16718.963 | D6: =AVERAGEIF('Cleaned Data'!$Q$8:$Q$507,A6,'Cleaned Data'!$P$8:$P$507) -> 699.56037 | E6: =AVERAGEIF('Cleaned Data'!$Q$8:$Q$507,A6,'Cleaned Data'!$N$8:$N$507) -> 44.898898
A7: Established (2010-2017) | B7: =COUNTIF('Cleaned Data'!$Q$8:$Q$507,A7) -> 207 | C7: =AVERAGEIF('Cleaned Data'!$Q$8:$Q$507,A7,'Cleaned Data'!$H$8:$H$507) -> 17719.422 | D7: =AVERAGEIF('Cleaned Data'!$Q$8:$Q$507,A7,'Cleaned Data'!$P$8:$P$507) -> 1427.8429 | E7: =AVERAGEIF('Cleaned Data'!$Q$8:$Q$507,A7,'Cleaned Data'!$N$8:$N$507) -> 54.161374
A8: Emerging (2018+) | B8: =COUNTIF('Cleaned Data'!$Q$8:$Q$507,A8) -> 39 | C8: =AVERAGEIF('Cleaned Data'!$Q$8:$Q$507,A8,'Cleaned Data'!$H$8:$H$507) -> 12673.541 | D8: =AVERAGEIF('Cleaned Data'!$Q$8:$Q$507,A8,'Cleaned Data'!$P$8:$P$507) -> 2034.1063 | E8: =AVERAGEIF('Cleaned Data'!$Q$8:$Q$507,A8,'Cleaned Data'!$N$8:$N$507) -> 53.275213

Sheet Q7 Gender Patterns
A1: Q7: Gender-Level Streaming & Collaboration Patterns
A3: Sex | B3: # Artists | C3: Avg Total Streams (M) | D3: Avg % Collaborative | E3: Avg % Solo
A4: Male | B4: =COUNTIF('Cleaned Data'!$B$8:$B$507,A4) -> 390 | C4: =AVERAGEIF('Cleaned Data'!$B$8:$B$507,A4,'Cleaned Data'!$H$8:$H$507) -> 16507.788 | D4: =AVERAGEIF('Cleaned Data'!$B$8:$B$507,A4,'Cleaned Data'!$N$8:$N$507) -> 51.420477 | E4: =AVERAGEIF('Cleaned Data'!$B$8:$B$507,A4,'Cleaned Data'!$L$8:$L$507) -> 48.579523
A5: Female | B5: =COUNTIF('Cleaned Data'!$B$8:$B$507,A5) -> 88 | C5: =AVERAGEIF('Cleaned Data'!$B$8:$B$507,A5,'Cleaned Data'!$H$8:$H$507) -> 18593.497 | D5: =AVERAGEIF('Cleaned Data'!$B$8:$B$507,A5,'Cleaned Data'!$N$8:$N$507) -> 44.623275 | E5: =AVERAGEIF('Cleaned Data'!$B$8:$B$507,A5,'Cleaned Data'!$L$8:$L$507) -> 55.376725
A6: Mixed | B6: =COUNTIF('Cleaned Data'!$B$8:$B$507,A6) -> 22 | C6: =AVERAGEIF('Cleaned Data'!$B$8:$B$507,A6,'Cleaned Data'!$H$8:$H$507) -> 15206.368 | D6: =AVERAGEIF('Cleaned Data'!$B$8:$B$507,A6,'Cleaned Data'!$N$8:$N$507) -> 32.391991 | E6: =AVERAGEIF('Cleaned Data'!$B$8:$B$507,A6,'Cleaned Data'!$L$8:$L$507) -> 67.608009
A8: Gender x Artist Type Crosstab (# Artists)
A9: Sex | B9: Solo | C9: Group
A10: Male | B10: =COUNTIFS('Cleaned Data'!$B$8:$B$507,A10,'Cleaned Data'!$F$8:$F$507,"Solo") -> 291 | C10: =COUNTIFS('Cleaned Data'!$B$8:$B$507,A10,'Cleaned Data'!$F$8:$F$507,"Group") -> 99
A11: Female | B11: =COUNTIFS('Cleaned Data'!$B$8:$B$507,A11,'Cleaned Data'!$F$8:$F$507,"Solo") -> 82 | C11: =COUNTIFS('Cleaned Data'!$B$8:$B$507,A11,'Cleaned Data'!$F$8:$F$507,"Group") -> 6
A12: Mixed | B12: =COUNTIFS('Cleaned Data'!$B$8:$B$507,A12,'Cleaned Data'!$F$8:$F$507,"Solo") -> 0 | C12: =COUNTIFS('Cleaned Data'!$B$8:$B$507,A12,'Cleaned Data'!$F$8:$F$507,"Group") -> 22

Sheet Charts
A1: Visualizations

Sheet Conclusions
A1: Conclusions & Recommended Actions
A2: Capstone question: based on Q1-7, what are the top actionable levers for maximizing streaming performance?
A4: 1. Market is genre-concentrated -- lead with Reggaeton/Pop/Hip-Hop/R&B
A5: Just 4 of 23 genres (Reggaeton, Pop, Hip-Hop, R&B) account for the largest share of total streams and post above-average streams per artist (18,400-20,700M avg vs. 16,818M dataset average). No genre met the strict criteria for a true "whitespace" opportunity (above-average streams AND below-median artist count) -- meaning there is no obvious underserved genre gap in this roster; the safest allocation of promotion budget is toward the 4 genres that are already proven, not a speculative niche bet.
A7: 2. Momentum beats tenure -- prioritize recent-debut, high-velocity artists
A8: Emerging artists (debuted 2018+) average 2,034M streams/year active vs. 1,428M for Established (2010-2017) and just 700M for Legacy (pre-2010) artists -- a ~3x momentum gap despite Emerging having the lowest average raw Total Streams (12,674M vs 16,719-17,719M for the other two groups, since they have had less time to accumulate). Bad Bunny, Olivia Rodrigo, and Peso Pluma post the single highest streams-per-year figures in the entire dataset. Decision: catalog value still favors legacy artists for guaranteed volume, but marketing/development budget aimed at growth should skew toward recent-debut artists showing this velocity.
A10: 3. Collaboration strategy has almost no linear effect on total streams
A11: The correlation between % Collaborative Streams and Total Streams is effectively 0 (see Q4 Charts CORREL value) -- both the 50-75% collab band (~20,433M avg) and the 25-50% band (~19,946M avg) modestly outperform the 0-25% band (~14,261M avg), but the 75-100% band drops back down (~15,191M avg). Decision: a moderate collaboration mix (roughly 25-75% of streams from features/collabs) outperforms both "all-solo" and "all-feature" strategies -- over-relying on collabs is not a reliable growth lever on its own.
A13: 4. Female artists slightly outperform on average, but the sample is smaller
A14: Female artists average 18,593M total streams vs. 16,508M for Male and 15,206M for Mixed-gender groups, and lean more solo-driven (55.4% solo streams vs. 48.6% for Male). However, Female artists are a smaller slice of the roster (88 of 500) vs. Male (390 of 500). Decision: this is a real average-performance edge worth noting for A&R, but not proof male artists underperform -- it is a smaller, possibly more selectively-signed group.
A16: 5. Bottom line -- 3 levers ranked by expected impact
A17: (1) Genre focus: keep budget concentrated in Reggaeton/Pop/Hip-Hop/R&B -- proven, not speculative. (2) Artist-stage mix: increase investment in recent-debut, high-streams/year artists to capture momentum before it plateaus, while keeping legacy artists for stable catalog volume. (3) Collaboration mix: target a moderate collab share (25-75%) per artist rather than pushing toward all-solo or all-feature releases, since both extremes underperform the middle band.
